Workbook

Sheet Registro Incidencias
A1: REGISTRO GENERAL DE INCIDENCIAS TÉCNICAS — CRA IBERCRA / GAMA SEGURIDAD
A2: ⚡ FUENTE ÚNICA DE DATOS — Administración rellena aquí → Se propaga automáticamente a hojas de técnicos | v6.0 | 2026
A3: 📋 IDENTIFICACIÓN | K3: 🔧 CLASIFICACIÓN Y ORIGEN | S3: 👷 ASIGNACIÓN | V3: ⏱ TIEMPOS, DESPLAZAMIENTO Y EJECUCIÓN | AF3: 📦 MATERIAL Y PRESUPUESTO | AK3: 📊 RESULTADO, COSTES Y RENDIMIENTO
A4: ID INCIDENCIA | B4: FECHA APERTURA | C4: HORA APERTURA | D4: N.º ABONADO | E4: ID CLIENTE | F4: CLIENTE / RAZÓN SOCIAL | G4: DIRECCIÓN | H4: MUNICIPIO | I4: PROVINCIA | J4: ENLACE UBICACIÓN | K4: TIPO INCIDENCIA | L4: PRIORIDAD | M4: ORIGEN INCIDENCIA | N4: PERSONA QUE ASIGNA | O4: SISTEMA AVERIADO | P4: EQUIPO / MODELO | Q4: ZONA / CÁMARA | R4: DESCRIPCIÓN INCIDENCIA | S4: TÉCNICO ASIGNADO | T4: FECHA PREVISTA VISITA | U4: HORA PREVISTA | V4: KM IDA | W4: KM VUELTA | X4: KM TOTALES | Y4: COSTE DESPLAZAMIENTO (€) | Z4: T. DESPLAZAMIENTO TOTAL (min) | AA4: T. ESTIMADO INCIDENCIA (min) | AB4: T. REAL INCIDENCIA (min) | AC4: T. TOTAL TRABAJO (min) | AD4: N.º VISITA | AE4: MOTIVO REVISITA | AF4: MATERIAL ASIGNADO | AG4: COSTE MATERIALES (€) | AH4: REQUIERE PRESUPUESTO | AI4: IMPORTE PRESUPUESTO (€) | AJ4: PRESUPUESTO ACEPTADO | AK4: ESTADO | AL4: RESULTADO FINAL | AM4: FECHA CIERRE | AN4: HORA CIERRE | AO4: T. RESOLUCIÓN (h) | AP4: COSTE HORA TÉC. (€/h) | AQ4: COSTE MANO OBRA (€) | AR4: COSTE DESPLAZ. (€) | AS4: COSTE TOTAL INCIDENCIA (€) | AT4: RENTABLE | AU4: VERIFICACIÓN NOCTURNA CRA | AV4: OPERADOR NOCTURNO | AW4: OBSERVACIONES / RESOLUCIÓN | AX4: _KEY | AY4: _N
A5: =IF(B5<>"","INC-"&TEXT(ROW()-4,"0000"),"") | X5: =IF(OR(V5<>"",W5<>""),IF(V5="",0,V5)+IF(W5="",0,W5),"") | Y5: =IF(X5<>"",X5*0.33,"") | AC5: =IF(OR(Z5<>"",AB5<>""),IF(Z5="",0,Z5)+IF(AB5="",0,AB5),"") | AO5: =IFERROR(IF(AND(AM5<>"",B5<>""),((AM5+AN5)-(B5+C5))*24,""),"") | AP5: =IF(S5="","",IF(S5="Juan Manuel",18.9,IF(S5="Juan Luis",17.5,IF(S5="Raúl",15.8,IF(S5="Adrián",13.5,IF(S5="Paco",13.5,"")))))) | AQ5: =IFERROR(IF(AND(AC5<>"",AP5<>""),(AC5/60)*AP5,""),"") | AR5: =IF(Y5<>"",Y5,"") | AS5: =IFERROR(IF(OR(AQ5<>"",AG5<>"",AR5<>""),IF(AQ5="",0,AQ5)+IF(AG5="",0,AG5)+IF(AR5="",0,AR5),""),"") | AT5: =IF(AS5="","",IF(AS5>150,"⚠️ REVISAR",IF(AS5>80,"⚡ ATENCIÓN","✅ OK"))) | AX5: =IF(OR(S5="",T5=""),"",S5&TEXT(T5,"YYYYMMDD")) | AY5: =IF(AX5="","",COUNTIF(AX$5:AX5,AX5))
A6: =IF(B6<>"","INC-"&TEXT(ROW()-4,"0000"),"") | X6: =IF(OR(V6<>"",W6<>""),IF(V6="",0,V6)+IF(W6="",0,W6),"") | Y6: =IF(X6<>"",X6*0.33,"") | AC6: =IF(OR(Z6<>"",AB6<>""),IF(Z6="",0,Z6)+IF(AB6="",0,AB6),"") | AO6: =IFERROR(IF(AND(AM6<>"",B6<>""),((AM6+AN6)-(B6+C6))*24,""),"") | AP6: =IF(S6="","",IF(S6="Juan Manuel",18.9,IF(S6="Juan Luis",17.5,IF(S6="Raúl",15.8,IF(S6="Adrián",13.5,IF(S6="Paco",13.5,"")))))) | AQ6: =IFERROR(IF(AND(AC6<>"",AP6<>""),(AC6/60)*AP6,""),"") | AR6: =IF(Y6<>"",Y6,"") | AS6: =IFERROR(IF(OR(AQ6<>"",AG6<>"",AR6<>""),IF(AQ6="",0,AQ6)+IF(AG6="",0,AG6)+IF(AR6="",0,AR6),""),"") | AT6: =IF(AS6="","",IF(AS6>150,"⚠️ REVISAR",IF(AS6>80,"⚡ ATENCIÓN","✅ OK"))) | AX6: =IF(OR(S6="",T6=""),"",S6&TEXT(T6,"YYYYMMDD")) | AY6: =IF(AX6="","",COUNTIF(AX$5:AX6,AX6))
A7: =IF(B7<>"","INC-"&TEXT(ROW()-4,"0000"),"") | X7: =IF(OR(V7<>"",W7<>""),IF(V7="",0,V7)+IF(W7="",0,W7),"") | Y7: =IF(X7<>"",X7*0.33,"") | AC7: =IF(OR(Z7<>"",AB7<>""),IF(Z7="",0,Z7)+IF(AB7="",0,AB7),"") | AO7: =IFERROR(IF(AND(AM7<>"",B7<>""),((AM7+AN7)-(B7+C7))*24,""),"") | AP7: =IF(S7="","",IF(S7="Juan Manuel",18.9,IF(S7="Juan Luis",17.5,IF(S7="Raúl",15.8,IF(S7="Adrián",13.5,IF(S7="Paco",13.5,"")))))) | AQ7: =IFERROR(IF(AND(AC7<>"",AP7<>""),(AC7/60)*AP7,""),"") | AR7: =IF(Y7<>"",Y7,"") | AS7: =IFERROR(IF(OR(AQ7<>"",AG7<>"",AR7<>""),IF(AQ7="",0,AQ7)+IF(AG7="",0,AG7)+IF(AR7="",0,AR7),""),"") | AT7: =IF(AS7="","",IF(AS7>150,"⚠️ REVISAR",IF(AS7>80,"⚡ ATENCIÓN","✅ OK"))) | AX7: =IF(OR(S7="",T7=""),"",S7&TEXT(T7,"YYYYMMDD")) | AY7: =IF(AX7="","",COUNTIF(AX$5:AX7,AX7))
A8: =IF(B8<>"","INC-"&TEXT(ROW()-4,"0000"),"") | X8: =IF(OR(V8<>"",W8<>""),IF(V8="",0,V8)+IF(W8="",0,W8),"") | Y8: =IF(X8<>"",X8*0.33,"") | AC8: =IF(OR(Z8<>"",AB8<>""),IF(Z8="",0,Z8)+IF(AB8="",0,AB8),"") | AO8: =IFERROR(IF(AND(AM8<>"",B8<>""),((AM8+AN8)-(B8+C8))*24,""),"") | AP8: =IF(S8="","",IF(S8="Juan Manuel",18.9,IF(S8="Juan Luis",17.5,IF(S8="Raúl",15.8,IF(S8="Adrián",13.5,IF(S8="Paco",13.5,"")))))) | AQ8: =IFERROR(IF(AND(AC8<>"",AP8<>""),(AC8/60)*AP8,""),"") | AR8: =IF(Y8<>"",Y8,"") | AS8: =IFERROR(IF(OR(AQ8<>"",AG8<>"",AR8<>""),IF(AQ8="",0,AQ8)+IF(AG8="",0,AG8)+IF(AR8="",0,AR8),""),"") | AT8: =IF(AS8="","",IF(AS8>150,"⚠️ REVISAR",IF(AS8>80,"⚡ ATENCIÓN","✅ OK"))) | AX8: =IF(OR(S8="",T8=""),"",S8&TEXT(T8,"YYYYMMDD")) | AY8: =IF(AX8="","",COUNTIF(AX$5:AX8,AX8))
A9: =IF(B9<>"","INC-"&TEXT(ROW()-4,"0000"),"") | X9: =IF(OR(V9<>"",W9<>""),IF(V9="",0,V9)+IF(W9="",0,W9),"") | Y9: =IF(X9<>"",X9*0.33,"") | AC9: =IF(OR(Z9<>"",AB9<>""),IF(Z9="",0,Z9)+IF(AB9="",0,AB9),"") | AO9: =IFERROR(IF(AND(AM9<>"",B9<>""),((AM9+AN9)-(B9+C9))*24,""),"") | AP9: =IF(S9="","",IF(S9="Juan Manuel",18.9,IF(S9="Juan Luis",17.5,IF(S9="Raúl",15.8,IF(S9="Adrián",13.5,IF(S9="Paco",13.5,"")))))) | AQ9: =IFERROR(IF(AND(AC9<>"",AP9<>""),(AC9/60)*AP9,""),"") | AR9: =IF(Y9<>"",Y9,"") | AS9: =IFERROR(IF(OR(AQ9<>"",AG9<>"",AR9<>""),IF(AQ9="",0,AQ9)+IF(AG9="",0,AG9)+IF(AR9="",0,AR9),""),"") | AT9: =IF(AS9="","",IF(AS9>150,"⚠️ REVISAR",IF(AS9>80,"⚡ ATENCIÓN","✅ OK"))) | AX9: =IF(OR(S9="",T9=""),"",S9&TEXT(T9,"YYYYMMDD")) | AY9: =IF(AX9="","",COUNTIF(AX$5:AX9,AX9))
A10: =IF(B10<>"","INC-"&TEXT(ROW()-4,"0000"),"") | X10: =IF(OR(V10<>"",W10<>""),IF(V10="",0,V10)+IF(W10="",0,W10),"") | Y10: =IF(X10<>"",X10*0.33,"") | AC10: =IF(OR(Z10<>"",AB10<>""),IF(Z10="",0,Z10)+IF(AB10="",0,AB10),"") | AO10: =IFERROR(IF(AND(AM10<>"",B10<>""),((AM10+AN10)-(B10+C10))*24,""),"") | AP10: =IF(S10="","",IF(S10="Juan Manuel",18.9,IF(S10="Juan Luis",17.5,IF(S10="Raúl",15.8,IF(S10="Adrián",13.5,IF(S10="Paco",13.5,"")))))) | AQ10: =IFERROR(IF(AND(AC10<>"",AP10<>""),(AC10/60)*AP10,""),"") | AR10: =IF(Y10<>"",Y10,"") | AS10: =IFERROR(IF(OR(AQ10<>"",AG10<>"",AR10<>""),IF(AQ10="",0,AQ10)+IF(AG10="",0,AG10)+IF(AR10="",0,AR10),""),"") | AT10: =IF(AS10="","",IF(AS10>150,"⚠️ REVISAR",IF(AS10>80,"⚡ ATENCIÓN","✅ OK"))) | AX10: =IF(OR(S10="",T10=""),"",S10&TEXT(T10,"YYYYMMDD")) | AY10: =IF(AX10="","",COUNTIF(AX$5:AX10,AX10))
A11: =IF(B11<>"","INC-"&TEXT(ROW()-4,"0000"),"") | X11: =IF(OR(V11<>"",W11<>""),IF(V11="",0,V11)+IF(W11="",0,W11),"") | Y11: =IF(X11<>"",X11*0.33,"") | AC11: =IF(OR(Z11<>"",AB11<>""),IF(Z11="",0,Z11)+IF(AB11="",0,AB11),"") | AO11: =IFERROR(IF(AND(AM11<>"",B11<>""),((AM11+AN11)-(B11+C11))*24,""),"") | AP11: =IF(S11="","",IF(S11="Juan Manuel",18.9,IF(S11="Juan Luis",17.5,IF(S11="Raúl",15.8,IF(S11="Adrián",13.5,IF(S11="Paco",13.5,"")))))) | AQ11: =IFERROR(IF(AND(AC11<>"",AP11<>""),(AC11/60)*AP11,""),"") | AR11: =IF(Y11<>"",Y11,"") | AS11: =IFERROR(IF(OR(AQ11<>"",AG11<>"",AR11<>""),IF(AQ11="",0,AQ11)+IF(AG11="",0,AG11)+IF(AR11="",0,AR11),""),"") | AT11: =IF(AS11="","",IF(AS11>150,"⚠️ REVISAR",IF(AS11>80,"⚡ ATENCIÓN","✅ OK"))) | AX11: =IF(OR(S11="",T11=""),"",S11&TEXT(T11,"YYYYMMDD")) | AY11: =IF(AX11="","",COUNTIF(AX$5:AX11,AX11))
A12: =IF(B12<>"","INC-"&TEXT(ROW()-4,"0000"),"") | X12: =IF(OR(V12<>"",W12<>""),IF(V12="",0,V12)+IF(W12="",0,W12),"") | Y12: =IF(X12<>"",X12*0.33,"") | AC12: =IF(OR(Z12<>"",AB12<>""),IF(Z12="",0,Z12)+IF(AB12="",0,AB12),"") | AO12: =IFERROR(IF(AND(AM12<>"",B12<>""),((AM12+AN12)-(B12+C12))*24,""),"") | AP12: =IF(S12="","",IF(S12="Juan Manuel",18.9,IF(S12="Juan Luis",17.5,IF(S12="Raúl",15.8,IF(S12="Adrián",13.5,IF(S12="Paco",13.5,"")))))) | AQ12: =IFERROR(IF(AND(AC12<>"",AP12<>""),(AC12/60)*AP12,""),"") | AR12: =IF(Y12<>"",Y12,"") | AS12: =IFERROR(IF(OR(AQ12<>"",AG12<>"",AR12<>""),IF(AQ12="",0,AQ12)+IF(AG12="",0,AG12)+IF(AR12="",0,AR12),""),"") | AT12: =IF(AS12="","",IF(AS12>150,"⚠️ REVISAR",IF(AS12>80,"⚡ ATENCIÓN","✅ OK"))) | AX12: =IF(OR(S12="",T12=""),"",S12&TEXT(T12,"YYYYMMDD")) | AY12: =IF(AX12="","",COUNTIF(AX$5:AX12,AX12))
A13: =IF(B13<>"","INC-"&TEXT(ROW()-4,"0000"),"") | X13: =IF(OR(V13<>"",W13<>""),IF(V13="",0,V13)+IF(W13="",0,W13),"") | Y13: =IF(X13<>"",X13*0.33,"") | AC13: =IF(OR(Z13<>"",AB13<>""),IF(Z13="",0,Z13)+IF(AB13="",0,AB13),"") | AO13: =IFERROR(IF(AND(AM13<>"",B13<>""),((AM13+AN13)-(B13+C13))*24,""),"") | AP13: =IF(S13="","",IF(S13="Juan Manuel",18.9,IF(S13="Juan Luis",17.5,IF(S13="Raúl",15.8,IF(S13="Adrián",13.5,IF(S13="Paco",13.5,"")))))) | AQ13: =IFERROR(IF(AND(AC13<>"",AP13<>""),(AC13/60)*AP13,""),"") | AR13: =IF(Y13<>"",Y13,"") | AS13: =IFERROR(IF(OR(AQ13<>"",AG13<>"",AR13<>""),IF(AQ13="",0,AQ13)+IF(AG13="",0,AG13)+IF(AR13="",0,AR13),""),"") | AT13: =IF(AS13="","",IF(AS13>150,"⚠️ REVISAR",IF(AS13>80,"⚡ ATENCIÓN","✅ OK"))) | AX13: =IF(OR(S13="",T13=""),"",S13&TEXT(T13,"YYYYMMDD")) | AY13: =IF(AX13="","",COUNTIF(AX$5:AX13,AX13))
A14: =IF(B14<>"","INC-"&TEXT(ROW()-4,"0000"),"") | X14: =IF(OR(V14<>"",W14<>""),IF(V14="",0,V14)+IF(W14="",0,W14),"") | Y14: =IF(X14<>"",X14*0.33,"") | AC14: =IF(OR(Z14<>"",AB14<>""),IF(Z14="",0,Z14)+IF(AB14="",0,AB14),"") | AO14: =IFERROR(IF(AND(AM14<>"",B14<>""),((AM14+AN14)-(B14+C14))*24,""),"") | AP14: =IF(S14="","",IF(S14="Juan Manuel",18.9,IF(S14="Juan Luis",17.5,IF(S14="Raúl",15.8,IF(S14="Adrián",13.5,IF(S14="Paco",13.5,"")))))) | AQ14: =IFERROR(IF(AND(AC14<>"",AP14<>""),(AC14/60)*AP14,""),"") | AR14: =IF(Y14<>"",Y14,"") | AS14: =IFERROR(IF(OR(AQ14<>"",AG14<>"",AR14<>""),IF(AQ14="",0,AQ14)+IF(AG14="",0,AG14)+IF(AR14="",0,AR14),""),"") | AT14: =IF(AS14="","",IF(AS14>150,"⚠️ REVISAR",IF(AS14>80,"⚡ ATENCIÓN","✅ OK"))) | AX14: =IF(OR(S14="",T14=""),"",S14&TEXT(T14,"YYYYMMDD")) | AY14: =IF(AX14="","",COUNTIF(AX$5:AX14,AX14))
A15: =IF(B15<>"","INC-"&TEXT(ROW()-4,"0000"),"") | X15: =IF(OR(V15<>"",W15<>""),IF(V15="",0,V15)+IF(W15="",0,W15),"") | Y15: =IF(X15<>"",X15*0.33,"") | AC15: =IF(OR(Z15<>"",AB15<>""),IF(Z15="",0,Z15)+IF(AB15="",0,AB15),"") | AO15: =IFERROR(IF(AND(AM15<>"",B15<>""),((AM15+AN15)-(B15+C15))*24,""),"") | AP15: =IF(S15="","",IF(S15="Juan Manuel",18.9,IF(S15="Juan Luis",17.5,IF(S15="Raúl",15.8,IF(S15="Adrián",13.5,IF(S15="Paco",13.5,"")))))) | AQ15: =IFERROR(IF(AND(AC15<>"",AP15<>""),(AC15/60)*AP15,""),"") | AR15: =IF(Y15<>"",Y15,"") | AS15: =IFERROR(IF(OR(AQ15<>"",AG15<>"",AR15<>""),IF(AQ15="",0,AQ15)+IF(AG15="",0,AG15)+IF(AR15="",0,AR15),""),"") | AT15: =IF(AS15="","",IF(AS15>150,"⚠️ REVISAR",IF(AS15>80,"⚡ ATENCIÓN","✅ OK"))) | AX15: =IF(OR(S15="",T15=""),"",S15&TEXT(T15,"YYYYMMDD")) | AY15: =IF(AX15="","",COUNTIF(AX$5:AX15,AX15))
A16: =IF(B16<>"","INC-"&TEXT(ROW()-4,"0000"),"") | X16: =IF(OR(V16<>"",W16<>""),IF(V16="",0,V16)+IF(W16="",0,W16),"") | Y16: =IF(X16<>"",X16*0.33,"") | AC16: =IF(OR(Z16<>"",AB16<>""),IF(Z16="",0,Z16)+IF(AB16="",0,AB16),"") | AO16: =IFERROR(IF(AND(AM16<>"",B16<>""),((AM16+AN16)-(B16+C16))*24,""),"") | AP16: =IF(S16="","",IF(S16="Juan Manuel",18.9,IF(S16="Juan Luis",17.5,IF(S16="Raúl",15.8,IF(S16="Adrián",13.5,IF(S16="Paco",13.5,"")))))) | AQ16: =IFERROR(IF(AND(AC16<>"",AP16<>""),(AC16/60)*AP16,""),"") | AR16: =IF(Y16<>"",Y16,"") | AS16: =IFERROR(IF(OR(AQ16<>"",AG16<>"",AR16<>""),IF(AQ16="",0,AQ16)+IF(AG16="",0,AG16)+IF(AR16="",0,AR16),""),"") | AT16: =IF(AS16="","",IF(AS16>150,"⚠️ REVISAR",IF(AS16>80,"⚡ ATENCIÓN","✅ OK"))) | AX16: =IF(OR(S16="",T16=""),"",S16&TEXT(T16,"YYYYMMDD")) | AY16: =IF(AX16="","",COUNTIF(AX$5:AX16,AX16))
... A200: =IF(B200<>"","INC-"&TEXT(ROW()-4,"0000"),"") | X200: =IF(OR(V200<>"",W200<>""),IF(V200="",0,V200)+IF(W200="",0,W200),"") | Y200: =IF(X200<>"",X200*0.33,"") | AC200: =IF(OR(Z200<>"",AB200<>""),IF(Z200="",0,Z200)+IF(AB200="",0,AB200),"") | AO200: =IFERROR(IF(AND(AM200<>"",B200<>""),((AM200+AN200)-(B200+C200))*24,""),"") | AP200: =IF(S200="","",IF(S200="Juan Manuel",18.9,IF(S200="Juan Luis",17.5,IF(S200="Raúl",15.8,IF(S200="Adrián",13.5,IF(S200="Paco",13.5,"")))))) | AQ200: =IFERROR(IF(AND(AC200<>"",AP200<>""),(AC200/60)*AP200,""),"") | AR200: =IF(Y200<>"",Y200,"") | AS200: =IFERROR(IF(OR(AQ200<>"",AG200<>"",AR200<>""),IF(AQ200="",0,AQ200)+IF(AG200="",0,AG200)+IF(AR200="",0,AR200),""),"") | AT200: =IF(AS200="","",IF(AS200>150,"⚠️ REVISAR",IF(AS200>80,"⚡ ATENCIÓN","✅ OK"))) | AX200: =IF(OR(S200="",T200=""),"",S200&TEXT(T200,"YYYYMMDD")) | AY200: =IF(AX200="","",COUNTIF(AX$5:AX200,AX200))

Sheet 📅 Semana
A1: CONFIGURACIÓN DE SEMANA
A2: ⚠️ Cambia la fecha del LUNES → todo se actualiza automáticamente
A4: FECHA DEL LUNES: | B4: 46069
A6: DÍA | B6: FECHA | C6: FESTIVO | D6: NOTAS | E6: AVERÍAS PROG.
A7: LUNES | B7: =B4+0 -> 46069 | E7: =COUNTIF('Registro Incidencias'!T$5:T$200,B7) -> 0
A8: MARTES | B8: =B4+1 -> 46070 | E8: =COUNTIF('Registro Incidencias'!T$5:T$200,B8) -> 0
A9: MIÉRCOLES | B9: =B4+2 -> 46071 | E9: =COUNTIF('Registro Incidencias'!T$5:T$200,B9) -> 0
A10: JUEVES | B10: =B4+3 -> 46072 | E10: =COUNTIF('Registro Incidencias'!T$5:T$200,B10) -> 0
A11: VIERNES | B11: =B4+4 -> 46073 | E11: =COUNTIF('Registro Incidencias'!T$5:T$200,B11) -> 0
A12: SÁBADO | B12: =B4+5 -> 46074 | E12: =COUNTIF('Registro Incidencias'!T$5:T$200,B12) -> 0
A13: DOMINGO | B13: =B4+6 -> 46075 | E13: =COUNTIF('Registro Incidencias'!T$5:T$200,B13) -> 0
A15: COSTES REFERENCIA
A16: TÉCNICO | B16: €/HORA | C16: TELÉFONO
A17: Raúl | B17: 15.8
A18: Juan Luis | B18: 17.5
A19: Paco | B19: 13.5
A20: Juan Manuel | B20: 18.9
A21: Adrián | B21: 13.5
A23: COSTE POR KM: | B23: 0.33

Sheet 📌 Raúl
A1: CALENDARIO SEMANAL — RAÚL (15.80 €/h)
A2: 🔄 Automático desde Registro | 🟢 Verde = Nocturna (Adrián / Christian / Alejandro)
A3: =TEXT('📅 Semana'!B$7,"DDDD")&" — "&TEXT('📅 Semana'!B$7,"DD/MM/")&"2026" -> lunes — 16/02/2026
A4: N.º | B4: HORA | C4: PRIORIDAD | D4: ID INCID. | E4: ABONADO | F4: CLIENTE | G4: DIRECCIÓN | H4: MUNICIPIO | I4: SISTEMA | J4: DESCRIPCIÓN | K4: MATERIAL | L4: PRESUP. | M4: VISITA | N4: MOTIVO REVISITA | O4: ESTADO | P4: 🟢 VERIFICACIÓN NOCTURNA | Q4: 🟢 OPERADOR | R4: 🟢 SISTEMA PENDIENTE | S4: 🟢 INFO EXTRA
A5: =IFERROR(MATCH(1,INDEX(('Registro Incidencias'!AX$5:AX$200="Raúl"&TEXT('📅 Semana'!B$7,"YYYYMMDD"))*('Registro Incidencias'!AY$5:AY$200=1),),0),"") | B5: =IF(A5="","",INDEX('Registro Incidencias'!U$5:U$200,A5)) | C5: =IF(A5="","",INDEX('Registro Incidencias'!L$5:L$200,A5)) | D5: =IF(A5="","",INDEX('Registro Incidencias'!A$5:A$200,A5)) | E5: =IF(A5="","",INDEX('Registro Incidencias'!D$5:D$200,A5)) | F5: =IF(A5="","",INDEX('Registro Incidencias'!F$5:F$200,A5)) | G5: =IF(A5="","",INDEX('Registro Incidencias'!G$5:G$200,A5)) | H5: =IF(A5="","",INDEX('Registro Incidencias'!H$5:H$200,A5)) | I5: =IF(A5="","",INDEX('Registro Incidencias'!O$5:O$200,A5)) | J5: =IF(A5="","",INDEX('Registro Incidencias'!R$5:R$200,A5)) | K5: =IF(A5="","",INDEX('Registro Incidencias'!AF$5:AF$200,A5)) | L5: =IF(A5="","",INDEX('Registro Incidencias'!AI$5:AI$200,A5)) | M5: =IF(A5="","",INDEX('Registro Incidencias'!AD$5:AD$200,A5)) | N5: =IF(A5="","",INDEX('Registro Incidencias'!AE$5:AE$200,A5)) | O5: =IF(A5="","",INDEX('Registro Incidencias'!AK$5:AK$200,A5)) | P5: =IF(A5="","",INDEX('Registro Incidencias'!AU$5:AU$200,A5)) | Q5: =IF(A5="","",INDEX('Registro Incidencias'!AV$5:AV$200,A5))
A6: =IFERROR(MATCH(1,INDEX(('Registro Incidencias'!AX$5:AX$200="Raúl"&TEXT('📅 Semana'!B$7,"YYYYMMDD"))*('Registro Incidencias'!AY$5:AY$200=2),),0),"") | B6: =IF(A6="","",INDEX('Registro Incidencias'!U$5:U$200,A6)) | C6: =IF(A6="","",INDEX('Registro Incidencias'!L$5:L$200,A6)) | D6: =IF(A6="","",INDEX('Registro Incidencias'!A$5:A$200,A6)) | E6: =IF(A6="","",INDEX('Registro Incidencias'!D$5:D$200,A6)) | F6: =IF(A6="","",INDEX('Registro Incidencias'!F$5:F$200,A6)) | G6: =IF(A6="","",INDEX('Registro Incidencias'!G$5:G$200,A6)) | H6: =IF(A6="","",INDEX('Registro Incidencias'!H$5:H$200,A6)) | I6: =IF(A6="","",INDEX('Registro Incidencias'!O$5:O$200,A6)) | J6: =IF(A6="","",INDEX('Registro Incidencias'!R$5:R$200,A6)) | K6: =IF(A6="","",INDEX('Registro Incidencias'!AF$5:AF$200,A6)) | L6: =IF(A6="","",INDEX('Registro Incidencias'!AI$5:AI$200,A6)) | M6: =IF(A6="","",INDEX('Registro Incidencias'!AD$5:AD$200,A6)) | N6: =IF(A6="","",INDEX('Registro Incidencias'!AE$5:AE$200,A6)) | O6: =IF(A6="","",INDEX('Registro Incidencias'!AK$5:AK$200,A6)) | P6: =IF(A6="","",INDEX('Registro Incidencias'!AU$5:AU$200,A6)) | Q6: =IF(A6="","",INDEX('Registro Incidencias'!AV$5:AV$200,A6))
A7: =IFERROR(MATCH(1,INDEX(('Registro Incidencias'!AX$5:AX$200="Raúl"&TEXT('📅 Semana'!B$7,"YYYYMMDD"))*('Registro Incidencias'!AY$5:AY$200=3),),0),"") | B7: =IF(A7="","",INDEX('Registro Incidencias'!U$5:U$200,A7)) | C7: =IF(A7="","",INDEX('Registro Incidencias'!L$5:L$200,A7)) | D7: =IF(A7="","",INDEX('Registro Incidencias'!A$5:A$200,A7)) | E7: =IF(A7="","",INDEX('Registro Incidencias'!D$5:D$200,A7)) | F7: =IF(A7="","",INDEX('Registro Incidencias'!F$5:F$200,A7)) | G7: =IF(A7="","",INDEX('Registro Incidencias'!G$5:G$200,A7)) | H7: =IF(A7="","",INDEX('Registro Incidencias'!H$5:H$200,A7)) | I7: =IF(A7="","",INDEX('Registro Incidencias'!O$5:O$200,A7)) | J7: =IF(A7="","",INDEX('Registro Incidencias'!R$5:R$200,A7)) | K7: =IF(A7="","",INDEX('Registro Incidencias'!AF$5:AF$200,A7)) | L7: =IF(A7="","",INDEX('Registro Incidencias'!AI$5:AI$200,A7)) | M7: =IF(A7="","",INDEX('Registro Incidencias'!AD$5:AD$200,A7)) | N7: =IF(A7="","",INDEX('Registro Incidencias'!AE$5:AE$200,A7)) | O7: =IF(A7="","",INDEX('Registro Incidencias'!AK$5:AK$200,A7)) | P7: =IF(A7="","",INDEX('Registro Incidencias'!AU$5:AU$200,A7)) | Q7: =IF(A7="","",INDEX('Registro Incidencias'!AV$5:AV$200,A7))
A8: =IFERROR(MATCH(1,INDEX(('Registro Incidencias'!AX$5:AX$200="Raúl"&TEXT('📅 Semana'!B$7,"YYYYMMDD"))*('Registro Incidencias'!AY$5:AY$200=4),),0),"") | B8: =IF(A8="","",INDEX('Registro Incidencias'!U$5:U$200,A8)) | C8: =IF(A8="","",INDEX('Registro Incidencias'!L$5:L$200,A8)) | D8: =IF(A8="","",INDEX('Registro Incidencias'!A$5:A$200,A8)) | E8: =IF(A8="","",INDEX('Registro Incidencias'!D$5:D$200,A8)) | F8: =IF(A8="","",INDEX('Registro Incidencias'!F$5:F$200,A8)) | G8: =IF(A8="","",INDEX('Registro Incidencias'!G$5:G$200,A8)) | H8: =IF(A8="","",INDEX('Registro Incidencias'!H$5:H$200,A8)) | I8: =IF(A8="","",INDEX('Registro Incidencias'!O$5:O$200,A8)) | J8: =IF(A8="","",INDEX('Registro Incidencias'!R$5:R$200,A8)) | K8: =IF(A8="","",INDEX('Registro Incidencias'!AF$5:AF$200,A8)) | L8: =IF(A8="","",INDEX('Registro Incidencias'!AI$5:AI$200,A8)) | M8: =IF(A8="","",INDEX('Registro Incidencias'!AD$5:AD$200,A8)) | N8: =IF(A8="","",INDEX('Registro Incidencias'!AE$5:AE$200,A8)) | O8: =IF(A8="","",INDEX('Registro Incidencias'!AK$5:AK$200,A8)) | P8: =IF(A8="","",INDEX('Registro Incidencias'!AU$5:AU$200,A8)) | Q8: =IF(A8="","",INDEX('Registro Incidencias'!AV$5:AV$200,A8))
A9: =IFERROR(MATCH(1,INDEX(('Registro Incidencias'!AX$5:AX$200="Raúl"&TEXT('📅 Semana'!B$7,"YYYYMMDD"))*('Registro Incidencias'!AY$5:AY$200=5),),0),"") | B9: =IF(A9="","",INDEX('Registro Incidencias'!U$5:U$200,A9)) | C9: =IF(A9="","",INDEX('Registro Incidencias'!L$5:L$200,A9)) | D9: =IF(A9="","",INDEX('Registro Incidencias'!A$5:A$200,A9)) | E9: =IF(A9="","",INDEX('Registro Incidencias'!D$5:D$200,A9)) | F9: =IF(A9="","",INDEX('Registro Incidencias'!F$5:F$200,A9)) | G9: =IF(A9="","",INDEX('Registro Incidencias'!G$5:G$200,A9)) | H9: =IF(A9="","",INDEX('Registro Incidencias'!H$5:H$200,A9)) | I9: =IF(A9="","",INDEX('Registro Incidencias'!O$5:O$200,A9)) | J9: =IF(A9="","",INDEX('Registro Incidencias'!R$5:R$200,A9)) | K9: =IF(A9="","",INDEX('Registro Incidencias'!AF$5:AF$200,A9)) | L9: =IF(A9="","",INDEX('Registro Incidencias'!AI$5:AI$200,A9)) | M9: =IF(A9="","",INDEX('Registro Incidencias'!AD$5:AD$200,A9)) | N9: =IF(A9="","",INDEX('Registro Incidencias'!AE$5:AE$200,A9)) | O9: =IF(A9="","",INDEX('Registro Incidencias'!AK$5:AK$200,A9)) | P9: =IF(A9="","",INDEX('Registro Incidencias'!AU$5:AU$200,A9)) | Q9: =IF(A9="","",INDEX('Registro Incidencias'!AV$5:AV$200,A9))
A10: =IFERROR(MATCH(1,INDEX(('Registro Incidencias'!AX$5:AX$200="Raúl"&TEXT('📅 Semana'!B$7,"YYYYMMDD"))*('Registro Incidencias'!AY$5:AY$200=6),),0),"") | B10: =IF(A10="","",INDEX('Registro Incidencias'!U$5:U$200,A10)) | C10: =IF(A10="","",INDEX('Registro Incidencias'!L$5:L$200,A10)) | D10: =IF(A10="","",INDEX('Registro Incidencias'!A$5:A$200,A10)) | E10: =IF(A10="","",INDEX('Registro Incidencias'!D$5:D$200,A10)) | F10: =IF(A10="","",INDEX('Registro Incidencias'!F$5:F$200,A10)) | G10: =IF(A10="","",INDEX('Registro Incidencias'!G$5:G$200,A10)) | H10: =IF(A10="","",INDEX('Registro Incidencias'!H$5:H$200,A10)) | I10: =IF(A10="","",INDEX('Registro Incidencias'!O$5:O$200,A10)) | J10: =IF(A10="","",INDEX('Registro Incidencias'!R$5:R$200,A10)) | K10: =IF(A10="","",INDEX('Registro Incidencias'!AF$5:AF$200,A10)) | L10: =IF(A10="","",INDEX('Registro Incidencias'!AI$5:AI$200,A10)) | M10: =IF(A10="","",INDEX('Registro Incidencias'!AD$5:AD$200,A10)) | N10: =IF(A10="","",INDEX('Registro Incidencias'!AE$5:AE$200,A10)) | O10: =IF(A10="","",INDEX('Registro Incidencias'!AK$5:AK$200,A10)) | P10: =IF(A10="","",INDEX('Registro Incidencias'!AU$5:AU$200,A10)) | Q10: =IF(A10="","",INDEX('Registro Incidencias'!AV$5:AV$200,A10))
A11: =COUNTIFS('Registro Incidencias'!S$5:S$200,"Raúl",'Registro Incidencias'!T$5:T$200,'📅 Semana'!B$7)&" averías" -> 0 averías | J11: ="Verificadas: "&COUNTIFS(A5:A10,"<>",P5:P10,"<>")&"/"&COUNTIF(A5:A10,"<>") -> Verificadas: 6/6
A13: =TEXT('📅 Semana'!B$8,"DDDD")&" — "&TEXT('📅 Semana'!B$8,"DD/MM/")&"2026" -> martes — 17/02/2026
A14: N.º | B14: HORA | C14: PRIORIDAD | D14: ID INCID. | E14: ABONADO | F14: CLIENTE | G14: DIRECCIÓN | H14: MUNICIPIO | I14: SISTEMA | J14: DESCRIPCIÓN | K14: MATERIAL | L14: PRESUP. | M14: VISITA | N14: MOTIVO REVISITA | O14: ESTADO | P14: 🟢 VERIFICACIÓN NOCTURNA | Q14: 🟢 OPERADOR | R14: 🟢 SISTEMA PENDIENTE | S14: 🟢 INFO EXTRA
A15: =IFERROR(MATCH(1,INDEX(('Registro Incidencias'!AX$5:AX$200="Raúl"&TEXT('📅 Semana'!B$8,"YYYYMMDD"))*('Registro Incidencias'!AY$5:AY$200=1),),0),"") | B15: =IF(A15="","",INDEX('Registro Incidencias'!U$5:U$200,A15)) | C15: =IF(A15="","",INDEX('Registro Incidencias'!L$5:L$200,A15)) | D15: =IF(A15="","",INDEX('Registro Incidencias'!A$5:A$200,A15)) | E15: =IF(A15="","",INDEX('Registro Incidencias'!D$5:D$200,A15)) | F15: =IF(A15="","",INDEX('Registro Incidencias'!F$5:F$200,A15)) | G15: =IF(A15="","",INDEX('Registro Incidencias'!G$5:G$200,A15)) | H15: =IF(A15="","",INDEX('Registro Incidencias'!H$5:H$200,A15)) | I15: =IF(A15="","",INDEX('Registro Incidencias'!O$5:O$200,A15)) | J15: =IF(A15="","",INDEX('Registro Incidencias'!R$5:R$200,A15)) | K15: =IF(A15="","",INDEX('Registro Incidencias'!AF$5:AF$200,A15)) | L15: =IF(A15="","",INDEX('Registro Incidencias'!AI$5:AI$200,A15)) | M15: =IF(A15="","",INDEX('Registro Incidencias'!AD$5:AD$200,A15)) | N15: =IF(A15="","",INDEX('Registro Incidencias'!AE$5:AE$200,A15)) | O15: =IF(A15="","",INDEX('Registro Incidencias'!AK$5:AK$200,A15)) | P15: =IF(A15="","",INDEX('Registro Incidencias'!AU$5:AU$200,A15)) | Q15: =IF(A15="","",INDEX('Registro Incidencias'!AV$5:AV$200,A15))
A16: =IFERROR(MATCH(1,INDEX(('Registro Incidencias'!AX$5:AX$200="Raúl"&TEXT('📅 Semana'!B$8,"YYYYMMDD"))*('Registro Incidencias'!AY$5:AY$200=2),),0),"") | B16: =IF(A16="","",INDEX('Registro Incidencias'!U$5:U$200,A16)) | C16: =IF(A16="","",INDEX('Registro Incidencias'!L$5:L$200,A16)) | D16: =IF(A16="","",INDEX('Registro Incidencias'!A$5:A$200,A16)) | E16: =IF(A16="","",INDEX('Registro Incidencias'!D$5:D$200,A16)) | F16: =IF(A16="","",INDEX('Registro Incidencias'!F$5:F$200,A16)) | G16: =IF(A16="","",INDEX('Registro Incidencias'!G$5:G$200,A16)) | H16: =IF(A16="","",INDEX('Registro Incidencias'!H$5:H$200,A16)) | I16: =IF(A16="","",INDEX('Registro Incidencias'!O$5:O$200,A16)) | J16: =IF(A16="","",INDEX('Registro Incidencias'!R$5:R$200,A16)) | K16: =IF(A16="","",INDEX('Registro Incidencias'!AF$5:AF$200,A16)) | L16: =IF(A16="","",INDEX('Registro Incidencias'!AI$5:AI$200,A16)) | M16: =IF(A16="","",INDEX('Registro Incidencias'!AD$5:AD$200,A16)) | N16: =IF(A16="","",INDEX('Registro Incidencias'!AE$5:AE$200,A16)) | O16: =IF(A16="","",INDEX('Registro Incidencias'!AK$5:AK$200,A16)) | P16: =IF(A16="","",INDEX('Registro Incidencias'!AU$5:AU$200,A16)) | Q16: =IF(A16="","",INDEX('Registro Incidencias'!AV$5:AV$200,A16))
A17: =IFERROR(MATCH(1,INDEX(('Registro Incidencias'!AX$5:AX$200="Raúl"&TEXT('📅 Semana'!B$8,"YYYYMMDD"))*('Registro Incidencias'!AY$5:AY$200=3),),0),"") | B17: =IF(A17="","",INDEX('Registro Incidencias'!U$5:U$200,A17)) | C17: =IF(A17="","",INDEX('Registro Incidencias'!L$5:L$200,A17)) | D17: =IF(A17="","",INDEX('Registro Incidencias'!A$5:A$200,A17)) | E17: =IF(A17="","",INDEX('Registro Incidencias'!D$5:D$200,A17)) | F17: =IF(A17="","",INDEX('Registro Incidencias'!F$5:F$200,A17)) | G17: =IF(A17="","",INDEX('Registro Incidencias'!G$5:G$200,A17)) | H17: =IF(A17="","",INDEX('Registro Incidencias'!H$5:H$200,A17)) | I17: =IF(A17="","",INDEX('Registro Incidencias'!O$5:O$200,A17)) | J17: =IF(A17="","",INDEX('Registro Incidencias'!R$5:R$200,A17)) | K17: =IF(A17="","",INDEX('Registro Incidencias'!AF$5:AF$200,A17)) | L17: =IF(A17="","",INDEX('Registro Incidencias'!AI$5:AI$200,A17)) | M17: =IF(A17="","",INDEX('Registro Incidencias'!AD$5:AD$200,A17)) | N17: =IF(A17="","",INDEX('Registro Incidencias'!AE$5:AE$200,A17)) | O17: =IF(A17="","",INDEX('Registro Incidencias'!AK$5:AK$200,A17)) | P17: =IF(A17="","",INDEX('Registro Incidencias'!AU$5:AU$200,A17)) | Q17: =IF(A17="","",INDEX('Registro Incidencias'!AV$5:AV$200,A17))
A18: =IFERROR(MATCH(1,INDEX(('Registro Incidencias'!AX$5:AX$200="Raúl"&TEXT('📅 Semana'!B$8,"YYYYMMDD"))*('Registro Incidencias'!AY$5:AY$200=4),),0),"") | B18: =IF(A18="","",INDEX('Registro Incidencias'!U$5:U$200,A18)) | C18: =IF(A18="","",INDEX('Registro Incidencias'!L$5:L$200,A18)) | D18: =IF(A18="","",INDEX('Registro Incidencias'!A$5:A$200,A18)) | E18: =IF(A18="","",INDEX('Registro Incidencias'!D$5:D$200,A18)) | F18: =IF(A18="","",INDEX('Registro Incidencias'!F$5:F$200,A18)) | G18: =IF(A18="","",INDEX('Registro Incidencias'!G$5:G$200,A18)) | H18: =IF(A18="","",INDEX('Registro Incidencias'!H$5:H$200,A18)) | I18: =IF(A18="","",INDEX('Registro Incidencias'!O$5:O$200,A18)) | J18: =IF(A18="","",INDEX('Registro Incidencias'!R$5:R$200,A18)) | K18: =IF(A18="","",INDEX('Registro Incidencias'!AF$5:AF$200,A18)) | L18: =IF(A18="","",INDEX('Registro Incidencias'!AI$5:AI$200,A18)) | M18: =IF(A18="","",INDEX('Registro Incidencias'!AD$5:AD$200,A18)) | N18: =IF(A18="","",INDEX('Registro Incidencias'!AE$5:AE$200,A18)) | O18: =IF(A18="","",INDEX('Registro Incidencias'!AK$5:AK$200,A18)) | P18: =IF(A18="","",INDEX('Registro Incidencias'!AU$5:AU$200,A18)) | Q18: =IF(A18="","",INDEX('Registro Incidencias'!AV$5:AV$200,A18))
A19: =IFERROR(MATCH(1,INDEX(('Registro Incidencias'!AX$5:AX$200="Raúl"&TEXT('📅 Semana'!B$8,"YYYYMMDD"))*('Registro Incidencias'!AY$5:AY$200=5),),0),"") | B19: =IF(A19="","",INDEX('Registro Incidencias'!U$5:U$200,A19)) | C19: =IF(A19="","",INDEX('Registro Incidencias'!L$5:L$200,A19)) | D19: =IF(A19="","",INDEX('Registro Incidencias'!A$5:A$200,A19)) | E19: =IF(A19="","",INDEX('Registro Incidencias'!D$5:D$200,A19)) | F19: =IF(A19="","",INDEX('Registro Incidencias'!F$5:F$200,A19)) | G19: =IF(A19="","",INDEX('Registro Incidencias'!G$5:G$200,A19)) | H19: =IF(A19="","",INDEX('Registro Incidencias'!H$5:H$200,A19)) | I19: =IF(A19="","",INDEX('Registro Incidencias'!O$5:O$200,A19)) | J19: =IF(A19="","",INDEX('Registro Incidencias'!R$5:R$200,A19)) | K19: =IF(A19="","",INDEX('Registro Incidencias'!AF$5:AF$200,A19)) | L19: =IF(A19="","",INDEX('Registro Incidencias'!AI$5:AI$200,A19)) | M19: =IF(A19="","",INDEX('Registro Incidencias'!AD$5:AD$200,A19)) | N19: =IF(A19="","",INDEX('Registro Incidencias'!AE$5:AE$200,A19)) | O19: =IF(A19="","",INDEX('Registro Incidencias'!AK$5:AK$200,A19)) | P19: =IF(A19="","",INDEX('Registro Incidencias'!AU$5:AU$200,A19)) | Q19: =IF(A19="","",INDEX('Registro Incidencias'!AV$5:AV$200,A19))
A20: =IFERROR(MATCH(1,INDEX(('Registro Incidencias'!AX$5:AX$200="Raúl"&TEXT('📅 Semana'!B$8,"YYYYMMDD"))*('Registro Incidencias'!AY$5:AY$200=6),),0),"") | B20: =IF(A20="","",INDEX('Registro Incidencias'!U$5:U$200,A20)) | C20: =IF(A20="","",INDEX('Registro Incidencias'!L$5:L$200,A20)) | D20: =IF(A20="","",INDEX('Registro Incidencias'!A$5:A$200,A20)) | E20: =IF(A20="","",INDEX('Registro Incidencias'!D$5:D$200,A20)) | F20: =IF(A20="","",INDEX('Registro Incidencias'!F$5:F$200,A20)) | G20: =IF(A20="","",INDEX('Registro Incidencias'!G$5:G$200,A20)) | H20: =IF(A20="","",INDEX('Registro Incidencias'!H$5:H$200,A20)) | I20: =IF(A20="","",INDEX('Registro Incidencias'!O$5:O$200,A20)) | J20: =IF(A20="","",INDEX('Registro Incidencias'!R$5:R$200,A20)) | K20: =IF(A20="","",INDEX('Registro Incidencias'!AF$5:AF$200,A20)) | L20: =IF(A20="","",INDEX('Registro Incidencias'!AI$5:AI$200,A20)) | M20: =IF(A20="","",INDEX('Registro Incidencias'!AD$5:AD$200,A20)) | N20: =IF(A20="","",INDEX('Registro Incidencias'!AE$5:AE$200,A20)) | O20: =IF(A20="","",INDEX('Registro Incidencias'!AK$5:AK$200,A20)) | P20: =IF(A20="","",INDEX('Registro Incidencias'!AU$5:AU$200,A20)) | Q20: =IF(A20="","",INDEX('Registro Incidencias'!AV$5:AV$200,A20))
A21: =COUNTIFS('Registro Incidencias'!S$5:S$200,"Raúl",'Registro Incidencias'!T$5:T$200,'📅 Semana'!B$8)&" averías" -> 0 averías | J21: ="Verificadas: "&COUNTIFS(A15:A20,"<>",P15:P20,"<>")&"/"&COUNTIF(A15:A20,"<>") -> Verificadas: 6/6
A23: =TEXT('📅 Semana'!B$9,"DDDD")&" — "&TEXT('📅 Semana'!B$9,"DD/MM/")&"2026" -> miércoles — 18/02/2026
A24: N.º | B24: HORA | C24: PRIORIDAD | D24: ID INCID. | E24: ABONADO | F24: CLIENTE | G24: DIRECCIÓN | H24: MUNICIPIO | I24: SISTEMA | J24: DESCRIPCIÓN | K24: MATERIAL | L24: PRESUP. | M24: VISITA | N24: MOTIVO REVISITA | O24: ESTADO | P24: 🟢 VERIFICACIÓN NOCTURNA | Q24: 🟢 OPERADOR | R24: 🟢 SISTEMA PENDIENTE | S24: 🟢 INFO EXTRA
A25: =IFERROR(MATCH(1,INDEX(('Registro Incidencias'!AX$5:AX$200="Raúl"&TEXT('📅 Semana'!B$9,"YYYYMMDD"))*('Registro Incidencias'!AY$5:AY$200=1),),0),"") | B25: =IF(A25="","",INDEX('Registro Incidencias'!U$5:U$200,A25)) | C25: =IF(A25="","",INDEX('Registro Incidencias'!L$5:L$200,A25)) | D25: =IF(A25="","",INDEX('Registro Incidencias'!A$5:A$200,A25)) | E25: =IF(A25="","",INDEX('Registro Incidencias'!D$5:D$200,A25)) | F25: =IF(A25="","",INDEX('Registro Incidencias'!F$5:F$200,A25)) | G25: =IF(A25="","",INDEX('Registro Incidencias'!G$5:G$200,A25)) | H25: =IF(A25="","",INDEX('Registro Incidencias'!H$5:H$200,A25)) | I25: =IF(A25="","",INDEX('Registro Incidencias'!O$5:O$200,A25)) | J25: =IF(A25="","",INDEX('Registro Incidencias'!R$5:R$200,A25)) | K25: =IF(A25="","",INDEX('Registro Incidencias'!AF$5:AF$200,A25)) | L25: =IF(A25="","",INDEX('Registro Incidencias'!AI$5:AI$200,A25)) | M25: =IF(A25="","",INDEX('Registro Incidencias'!AD$5:AD$200,A25)) | N25: =IF(A25="","",INDEX('Registro Incidencias'!AE$5:AE$200,A25)) | O25: =IF(A25="","",INDEX('Registro Incidencias'!AK$5:AK$200,A25)) | P25: =IF(A25="","",INDEX('Registro Incidencias'!AU$5:AU$200,A25)) | Q25: =IF(A25="","",INDEX('Registro Incidencias'!AV$5:AV$200,A25))
A26: =IFERROR(MATCH(1,INDEX(('Registro Incidencias'!AX$5:AX$200="Raúl"&TEXT('📅 Semana'!B$9,"YYYYMMDD"))*('Registro Incidencias'!AY$5:AY$200=2),),0),"") | B26: =IF(A26="","",INDEX('Registro Incidencias'!U$5:U$200,A26)) | C26: =IF(A26="","",INDEX('Registro Incidencias'!L$5:L$200,A26)) | D26: =IF(A26="","",INDEX('Registro Incidencias'!A$5:A$200,A26)) | E26: =IF(A26="","",INDEX('Registro Incidencias'!D$5:D$200,A26)) | F26: =IF(A26="","",INDEX('Registro Incidencias'!F$5:F$200,A26)) | G26: =IF(A26="","",INDEX('Registro Incidencias'!G$5:G$200,A26)) | H26: =IF(A26="","",INDEX('Registro Incidencias'!H$5:H$200,A26)) | I26: =IF(A26="","",INDEX('Registro Incidencias'!O$5:O$200,A26)) | J26: =IF(A26="","",INDEX('Registro Incidencias'!R$5:R$200,A26)) | K26: =IF(A26="","",INDEX('Registro Incidencias'!AF$5:AF$200,A26)) | L26: =IF(A26="","",INDEX('Registro Incidencias'!AI$5:AI$200,A26)) | M26: =IF(A26="","",INDEX('Registro Incidencias'!AD$5:AD$200,A26)) | N26: =IF(A26="","",INDEX('Registro Incidencias'!AE$5:AE$200,A26)) | O26: =IF(A26="","",INDEX('Registro Incidencias'!AK$5:AK$200,A26)) | P26: =IF(A26="","",INDEX('Registro Incidencias'!AU$5:AU$200,A26)) | Q26: =IF(A26="","",INDEX('Registro Incidencias'!AV$5:AV$200,A26))
A27: =IFERROR(MATCH(1,INDEX(('Registro Incidencias'!AX$5:AX$200="Raúl"&TEXT('📅 Semana'!B$9,"YYYYMMDD"))*('Registro Incidencias'!AY$5:AY$200=3),),0),"") | B27: =IF(A27="","",INDEX('Registro Incidencias'!U$5:U$200,A27)) | C27: =IF(A27="","",INDEX('Registro Incidencias'!L$5:L$200,A27)) | D27: =IF(A27="","",INDEX('Registro Incidencias'!A$5:A$200,A27)) | E27: =IF(A27="","",INDEX('Registro Incidencias'!D$5:D$200,A27)) | F27: =IF(A27="","",INDEX('Registro Incidencias'!F$5:F$200,A27)) | G27: =IF(A27="","",INDEX('Registro Incidencias'!G$5:G$200,A27)) | H27: =IF(A27="","",INDEX('Registro Incidencias'!H$5:H$200,A27)) | I27: =IF(A27="","",INDEX('Registro Incidencias'!O$5:O$200,A27)) | J27: =IF(A27="","",INDEX('Registro Incidencias'!R$5:R$200,A27)) | K27: =IF(A27="","",INDEX('Registro Incidencias'!AF$5:AF$200,A27)) | L27: =IF(A27="","",INDEX('Registro Incidencias'!AI$5:AI$200,A27)) | M27: =IF(A27="","",INDEX('Registro Incidencias'!AD$5:AD$200,A27)) | N27: =IF(A27="","",INDEX('Registro Incidencias'!AE$5:AE$200,A27)) | O27: =IF(A27="","",INDEX('Registro Incidencias'!AK$5:AK$200,A27)) | P27: =IF(A27="","",INDEX('Registro Incidencias'!AU$5:AU$200,A27)) | Q27: =IF(A27="","",INDEX('Registro Incidencias'!AV$5:AV$200,A27))
A28: =IFERROR(MATCH(1,INDEX(('Registro Incidencias'!AX$5:AX$200="Raúl"&TEXT('📅 Semana'!B$9,"YYYYMMDD"))*('Registro Incidencias'!AY$5:AY$200=4),),0),"") | B28: =IF(A28="","",INDEX('Registro Incidencias'!U$5:U$200,A28)) | C28: =IF(A28="","",INDEX('Registro Incidencias'!L$5:L$200,A28)) | D28: =IF(A28="","",INDEX('Registro Incidencias'!A$5:A$200,A28)) | E28: =IF(A28="","",INDEX('Registro Incidencias'!D$5:D$200,A28)) | F28: =IF(A28="","",INDEX('Registro Incidencias'!F$5:F$200,A28)) | G28: =IF(A28="","",INDEX('Registro Incidencias'!G$5:G$200,A28)) | H28: =IF(A28="","",INDEX('Registro Incidencias'!H$5:H$200,A28)) | I28: =IF(A28="","",INDEX('Registro Incidencias'!O$5:O$200,A28)) | J28: =IF(A28="","",INDEX('Registro Incidencias'!R$5:R$200,A28)) | K28: =IF(A28="","",INDEX('Registro Incidencias'!AF$5:AF$200,A28)) | L28: =IF(A28="","",INDEX('Registro Incidencias'!AI$5:AI$200,A28)) | M28: =IF(A28="","",INDEX('Registro Incidencias'!AD$5:AD$200,A28)) | N28: =IF(A28="","",INDEX('Registro Incidencias'!AE$5:AE$200,A28)) | O28: =IF(A28="","",INDEX('Registro Incidencias'!AK$5:AK$200,A28)) | P28: =IF(A28="","",INDEX('Registro Incidencias'!AU$5:AU$200,A28)) | Q28: =IF(A28="","",INDEX('Registro Incidencias'!AV$5:AV$200,A28))
A29: =IFERROR(MATCH(1,INDEX(('Registro Incidencias'!AX$5:AX$200="Raúl"&TEXT('📅 Semana'!B$9,"YYYYMMDD"))*('Registro Incidencias'!AY$5:AY$200=5),),0),"") | B29: =IF(A29="","",INDEX('Registro Incidencias'!U$5:U$200,A29)) | C29: =IF(A29="","",INDEX('Registro Incidencias'!L$5:L$200,A29)) | D29: =IF(A29="","",INDEX('Registro Incidencias'!A$5:A$200,A29)) | E29: =IF(A29="","",INDEX('Registro Incidencias'!D$5:D$200,A29)) | F29: =IF(A29="","",INDEX('Registro Incidencias'!F$5:F$200,A29)) | G29: =IF(A29="","",INDEX('Registro Incidencias'!G$5:G$200,A29)) | H29: =IF(A29="","",INDEX('Registro Incidencias'!H$5:H$200,A29)) | I29: =IF(A29="","",INDEX('Registro Incidencias'!O$5:O$200,A29)) | J29: =IF(A29="","",INDEX('Registro Incidencias'!R$5:R$200,A29)) | K29: =IF(A29="","",INDEX('Registro Incidencias'!AF$5:AF$200,A29)) | L29: =IF(A29="","",INDEX('Registro Incidencias'!AI$5:AI$200,A29)) | M29: =IF(A29="","",INDEX('Registro Incidencias'!AD$5:AD$200,A29)) | N29: =IF(A29="","",INDEX('Registro Incidencias'!AE$5:AE$200,A29)) | O29: =IF(A29="","",INDEX('Registro Incidencias'!AK$5:AK$200,A29)) | P29: =IF(A29="","",INDEX('Registro Incidencias'!AU$5:AU$200,A29)) | Q29: =IF(A29="","",INDEX('Registro Incidencias'!AV$5:AV$200,A29))
A30: =IFERROR(MATCH(1,INDEX(('Registro Incidencias'!AX$5:AX$200="Raúl"&TEXT('📅 Semana'!B$9,"YYYYMMDD"))*('Registro Incidencias'!AY$5:AY$200=6),),0),"") | B30: =IF(A30="","",INDEX('Registro Incidencias'!U$5:U$200,A30)) | C30: =IF(A30="","",INDEX('Registro Incidencias'!L$5:L$200,A30)) | D30: =IF(A30="","",INDEX('Registro Incidencias'!A$5:A$200,A30)) | E30: =IF(A30="","",INDEX('Registro Incidencias'!D$5:D$200,A30)) | F30: =IF(A30="","",INDEX('Registro Incidencias'!F$5:F$200,A30)) | G30: =IF(A30="","",INDEX('Registro Incidencias'!G$5:G$200,A30)) | H30: =IF(A30="","",INDEX('Registro Incidencias'!H$5:H$200,A30)) | I30: =IF(A30="","",INDEX('Registro Incidencias'!O$5:O$200,A30)) | J30: =IF(A30="","",INDEX('Registro Incidencias'!R$5:R$200,A30)) | K30: =IF(A30="","",INDEX('Registro Incidencias'!AF$5:AF$200,A30)) | L30: =IF(A30="","",INDEX('Registro Incidencias'!AI$5:AI$200,A30)) | M30: =IF(A30="","",INDEX('Registro Incidencias'!AD$5:AD$200,A30)) | N30: =IF(A30="","",INDEX('Registro Incidencias'!AE$5:AE$200,A30)) | O30: =IF(A30="","",INDEX('Registro Incidencias'!AK$5:AK$200,A30)) | P30: =IF(A30="","",INDEX('Registro Incidencias'!AU$5:AU$200,A30)) | Q30: =IF(A30="","",INDEX('Registro Incidencias'!AV$5:AV$200,A30))
A31: =COUNTIFS('Registro Incidencias'!S$5:S$200,"Raúl",'Registro Incidencias'!T$5:T$200,'📅 Semana'!B$9)&" averías" -> 0 averías | J31: ="Verificadas: "&COUNTIFS(A25:A30,"<>",P25:P30,"<>")&"/"&COUNTIF(A25:A30,"<>") -> Verificadas: 6/6
A33: =TEXT('📅 Semana'!B$10,"DDDD")&" — "&TEXT('📅 Semana'!B$10,"DD/MM/")&"2026" -> jueves — 19/02/2026
A34: N.º | B34: HORA | C34: PRIORIDAD | D34: ID INCID. | E34: ABONADO | F34: CLIENTE | G34: DIRECCIÓN | H34: MUNICIPIO | I34: SISTEMA | J34: DESCRIPCIÓN | K34: MATERIAL | L34: PRESUP. | M34: VISITA | N34: MOTIVO REVISITA | O34: ESTADO | P34: 🟢 VERIFICACIÓN NOCTURNA | Q34: 🟢 OPERADOR | R34: 🟢 SISTEMA PENDIENTE | S34: 🟢 INFO EXTRA
A35: =IFERROR(MATCH(1,INDEX(('Registro Incidencias'!AX$5:AX$200="Raúl"&TEXT('📅 Semana'!B$10,"YYYYMMDD"))*('Registro Incidencias'!AY$5:AY$200=1),),0),"") | B35: =IF(A35="","",INDEX('Registro Incidencias'!U$5:U$200,A35)) | C35: =IF(A35="","",INDEX('Registro Incidencias'!L$5:L$200,A35)) | D35: =IF(A35="","",INDEX('Registro Incidencias'!A$5:A$200,A35)) | E35: =IF(A35="","",INDEX('Registro Incidencias'!D$5:D$200,A35)) | F35: =IF(A35="","",INDEX('Registro Incidencias'!F$5:F$200,A35)) | G35: =IF(A35="","",INDEX('Registro Incidencias'!G$5:G$200,A35)) | H35: =IF(A35="","",INDEX('Registro Incidencias'!H$5:H$200,A35)) | I35: =IF(A35="","",INDEX('Registro Incidencias'!O$5:O$200,A35)) | J35: =IF(A35="","",INDEX('Registro Incidencias'!R$5:R$200,A35)) | K35: =IF(A35="","",INDEX('Registro Incidencias'!AF$5:AF$200,A35)) | L35: =IF(A35="","",INDEX('Registro Incidencias'!AI$5:AI$200,A35)) | M35: =IF(A35="","",INDEX('Registro Incidencias'!AD$5:AD$200,A35)) | N35: =IF(A35="","",INDEX('Registro Incidencias'!AE$5:AE$200,A35)) | O35: =IF(A35="","",INDEX('Registro Incidencias'!AK$5:AK$200,A35)) | P35: =IF(A35="","",INDEX('Registro Incidencias'!AU$5:AU$200,A35)) | Q35: =IF(A35="","",INDEX('Registro Incidencias'!AV$5:AV$200,A35))
A36: =IFERROR(MATCH(1,INDEX(('Registro Incidencias'!AX$5:AX$200="Raúl"&TEXT('📅 Semana'!B$10,"YYYYMMDD"))*('Registro Incidencias'!AY$5:AY$200=2),),0),"") | B36: =IF(A36="","",INDEX('Registro Incidencias'!U$5:U$200,A36)) | C36: =IF(A36="","",INDEX('Registro Incidencias'!L$5:L$200,A36)) | D36: =IF(A36="","",INDEX('Registro Incidencias'!A$5:A$200,A36)) | E36: =IF(A36="","",INDEX('Registro Incidencias'!D$5:D$200,A36)) | F36: =IF(A36="","",INDEX('Registro Incidencias'!F$5:F$200,A36)) | G36: =IF(A36="","",INDEX('Registro Incidencias'!G$5:G$200,A36)) | H36: =IF(A36="","",INDEX('Registro Incidencias'!H$5:H$200,A36)) | I36: =IF(A36="","",INDEX('Registro Incidencias'!O$5:O$200,A36)) | J36: =IF(A36="","",INDEX('Registro Incidencias'!R$5:R$200,A36)) | K36: =IF(A36="","",INDEX('Registro Incidencias'!AF$5:AF$200,A36)) | L36: =IF(A36="","",INDEX('Registro Incidencias'!AI$5:AI$200,A36)) | M36: =IF(A36="","",INDEX('Registro Incidencias'!AD$5:AD$200,A36)) | N36: =IF(A36="","",INDEX('Registro Incidencias'!AE$5:AE$200,A36)) | O36: =IF(A36="","",INDEX('Registro Incidencias'!AK$5:AK$200,A36)) | P36: =IF(A36="","",INDEX('Registro Incidencias'!AU$5:AU$200,A36)) | Q36: =IF(A36="","",INDEX('Registro Incidencias'!AV$5:AV$200,A36))
A37: =IFERROR(MATCH(1,INDEX(('Registro Incidencias'!AX$5:AX$200="Raúl"&TEXT('📅 Semana'!B$10,"YYYYMMDD"))*('Registro Incidencias'!AY$5:AY$200=3),),0),"") | B37: =IF(A37="","",INDEX('Registro Incidencias'!U$5:U$200,A37)) | C37: =IF(A37="","",INDEX('Registro Incidencias'!L$5:L$200,A37)) | D37: =IF(A37="","",INDEX('Registro Incidencias'!A$5:A$200,A37)) | E37: =IF(A37="","",INDEX('Registro Incidencias'!D$5:D$200,A37)) | F37: =IF(A37="","",INDEX('Registro Incidencias'!F$5:F$200,A37)) | G37: =IF(A37="","",INDEX('Registro Incidencias'!G$5:G$200,A37)) | H37: =IF(A37="","",INDEX('Registro Incidencias'!H$5:H$200,A37)) | I37: =IF(A37="","",INDEX('Registro Incidencias'!O$5:O$200,A37)) | J37: =IF(A37="","",INDEX('Registro Incidencias'!R$5:R$200,A37)) | K37: =IF(A37="","",INDEX('Registro Incidencias'!AF$5:AF$200,A37)) | L37: =IF(A37="","",INDEX('Registro Incidencias'!AI$5:AI$200,A37)) | M37: =IF(A37="","",INDEX('Registro Incidencias'!AD$5:AD$200,A37)) | N37: =IF(A37="","",INDEX('Registro Incidencias'!AE$5:AE$200,A37)) | O37: =IF(A37="","",INDEX('Registro Incidencias'!AK$5:AK$200,A37)) | P37: =IF(A37="","",INDEX('Registro Incidencias'!AU$5:AU$200,A37)) | Q37: =IF(A37="","",INDEX('Registro Incidencias'!AV$5:AV$200,A37))
A38: =IFERROR(MATCH(1,INDEX(('Registro Incidencias'!AX$5:AX$200="Raúl"&TEXT('📅 Semana'!B$10,"YYYYMMDD"))*('Registro Incidencias'!AY$5:AY$200=4),),0),"") | B38: =IF(A38="","",INDEX('Registro Incidencias'!U$5:U$200,A38)) | C38: =IF(A38="","",INDEX('Registro Incidencias'!L$5:L$200,A38)) | D38: =IF(A38="","",INDEX('Registro Incidencias'!A$5:A$200,A38)) | E38: =IF(A38="","",INDEX('Registro Incidencias'!D$5:D$200,A38)) | F38: =IF(A38="","",INDEX('Registro Incidencias'!F$5:F$200,A38)) | G38: =IF(A38="","",INDEX('Registro Incidencias'!G$5:G$200,A38)) | H38: =IF(A38="","",INDEX('Registro Incidencias'!H$5:H$200,A38)) | I38: =IF(A38="","",INDEX('Registro Incidencias'!O$5:O$200,A38)) | J38: =IF(A38="","",INDEX('Registro Incidencias'!R$5:R$200,A38)) | K38: =IF(A38="","",INDEX('Registro Incidencias'!AF$5:AF$200,A38)) | L38: =IF(A38="","",INDEX('Registro Incidencias'!AI$5:AI$200,A38)) | M38: =IF(A38="","",INDEX('Registro Incidencias'!AD$5:AD$200,A38)) | N38: =IF(A38="","",INDEX('Registro Incidencias'!AE$5:AE$200,A38)) | O38: =IF(A38="","",INDEX('Registro Incidencias'!AK$5:AK$200,A38)) | P38: =IF(A38="","",INDEX('Registro Incidencias'!AU$5:AU$200,A38)) | Q38: =IF(A38="","",INDEX('Registro Incidencias'!AV$5:AV$200,A38))
A39: =IFERROR(MATCH(1,INDEX(('Registro Incidencias'!AX$5:AX$200="Raúl"&TEXT('📅 Semana'!B$10,"YYYYMMDD"))*('Registro Incidencias'!AY$5:AY$200=5),),0),"") | B39: =IF(A39="","",INDEX('Registro Incidencias'!U$5:U$200,A39)) | C39: =IF(A39="","",INDEX('Registro Incidencias'!L$5:L$200,A39)) | D39: =IF(A39="","",INDEX('Registro Incidencias'!A$5:A$200,A39)) | E39: =IF(A39="","",INDEX('Registro Incidencias'!D$5:D$200,A39)) | F39: =IF(A39="","",INDEX('Registro Incidencias'!F$5:F$200,A39)) | G39: =IF(A39="","",INDEX('Registro Incidencias'!G$5:G$200,A39)) | H39: =IF(A39="","",INDEX('Registro Incidencias'!H$5:H$200,A39)) | I39: =IF(A39="","",INDEX('Registro Incidencias'!O$5:O$200,A39)) | J39: =IF(A39="","",INDEX('Registro Incidencias'!R$5:R$200,A39)) | K39: =IF(A39="","",INDEX('Registro Incidencias'!AF$5:AF$200,A39)) | L39: =IF(A39="","",INDEX('Registro Incidencias'!AI$5:AI$200,A39)) | M39: =IF(A39="","",INDEX('Registro Incidencias'!AD$5:AD$200,A39)) | N39: =IF(A39="","",INDEX('Registro Incidencias'!AE$5:AE$200,A39)) | O39: =IF(A39="","",INDEX('Registro Incidencias'!AK$5:AK$200,A39)) | P39: =IF(A39="","",INDEX('Registro Incidencias'!AU$5:AU$200,A39)) | Q39: =IF(A39="","",INDEX('Registro Incidencias'!AV$5:AV$200,A39))
A40: =IFERROR(MATCH(1,INDEX(('Registro Incidencias'!AX$5:AX$200="Raúl"&TEXT('📅 Semana'!B$10,"YYYYMMDD"))*('Registro Incidencias'!AY$5:AY$200=6),),0),"") | B40: =IF(A40="","",INDEX('Registro Incidencias'!U$5:U$200,A40)) | C40: =IF(A40="","",INDEX('Registro Incidencias'!L$5:L$200,A40)) | D40: =IF(A40="","",INDEX('Registro Incidencias'!A$5:A$200,A40)) | E40: =IF(A40="","",INDEX('Registro Incidencias'!D$5:D$200,A40)) | F40: =IF(A40="","",INDEX('Registro Incidencias'!F$5:F$200,A40)) | G40: =IF(A40="","",INDEX('Registro Incidencias'!G$5:G$200,A40)) | H40: =IF(A40="","",INDEX('Registro Incidencias'!H$5:H$200,A40)) | I40: =IF(A40="","",INDEX('Registro Incidencias'!O$5:O$200,A40)) | J40: =IF(A40="","",INDEX('Registro Incidencias'!R$5:R$200,A40)) | K40: =IF(A40="","",INDEX('Registro Incidencias'!AF$5:AF$200,A40)) | L40: =IF(A40="","",INDEX('Registro Incidencias'!AI$5:AI$200,A40)) | M40: =IF(A40="","",INDEX('Registro Incidencias'!AD$5:AD$200,A40)) | N40: =IF(A40="","",INDEX('Registro Incidencias'!AE$5:AE$200,A40)) | O40: =IF(A40="","",INDEX('Registro Incidencias'!AK$5:AK$200,A40)) | P40: =IF(A40="","",INDEX('Registro Incidencias'!AU$5:AU$200,A40)) | Q40: =IF(A40="","",INDEX('Registro Incidencias'!AV$5:AV$200,A40))
A41: =COUNTIFS('Registro Incidencias'!S$5:S$200,"Raúl",'Registro Incidencias'!T$5:T$200,'📅 Semana'!B$10)&" averías" -> 0 averías | J41: ="Verificadas: "&COUNTIFS(A35:A40,"<>",P35:P40,"<>")&"/"&COUNTIF(A35:A40,"<>") -> Verificadas: 6/6
A43: =TEXT('📅 Semana'!B$11,"DDDD")&" — "&TEXT('📅 Semana'!B$11,"DD/MM/")&"2026" -> viernes — 20/02/2026
A44: N.º | B44: HORA | C44: PRIORIDAD | D44: ID INCID. | E44: ABONADO | F44: CLIENTE | G44: DIRECCIÓN | H44: MUNICIPIO | I44: SISTEMA | J44: DESCRIPCIÓN | K44: MATERIAL | L44: PRESUP. | M44: VISITA | N44: MOTIVO REVISITA | O44: ESTADO | P44: 🟢 VERIFICACIÓN NOCTURNA | Q44: 🟢 OPERADOR | R44: 🟢 SISTEMA PENDIENTE | S44: 🟢 INFO EXTRA
...

Sheet 📌 Juan Luis
A1: CALENDARIO SEMANAL — JUAN LUIS (17.50 €/h)
A2: 🔄 Automático desde Registro | 🟢 Verde = Nocturna (Adrián / Christian / Alejandro)
A3: =TEXT('📅 Semana'!B$7,"DDDD")&" — "&TEXT('📅 Semana'!B$7,"DD/MM/")&"2026" -> lunes — 16/02/2026
A4: N.º | B4: HORA | C4: PRIORIDAD | D4: ID INCID. | E4: ABONADO | F4: CLIENTE | G4: DIRECCIÓN | H4: MUNICIPIO | I4: SISTEMA | J4: DESCRIPCIÓN | K4: MATERIAL | L4: PRESUP. | M4: VISITA | N4: MOTIVO REVISITA | O4: ESTADO | P4: 🟢 VERIFICACIÓN NOCTURNA | Q4: 🟢 OPERADOR | R4: 🟢 SISTEMA PENDIENTE | S4: 🟢 INFO EXTRA
A5: =IFERROR(MATCH(1,INDEX(('Registro Incidencias'!AX$5:AX$200="Juan Luis"&TEXT('📅 Semana'!B$7,"YYYYMMDD"))*('Registro Incidencias'!AY$5:AY$200=1),),0),"") | B5: =IF(A5="","",INDEX('Registro Incidencias'!U$5:U$200,A5)) | C5: =IF(A5="","",INDEX('Registro Incidencias'!L$5:L$200,A5)) | D5: =IF(A5="","",INDEX('Registro Incidencias'!A$5:A$200,A5)) | E5: =IF(A5="","",INDEX('Registro Incidencias'!D$5:D$200,A5)) | F5: =IF(A5="","",INDEX('Registro Incidencias'!F$5:F$200,A5)) | G5: =IF(A5="","",INDEX('Registro Incidencias'!G$5:G$200,A5)) | H5: =IF(A5="","",INDEX('Registro Incidencias'!H$5:H$200,A5)) | I5: =IF(A5="","",INDEX('Registro Incidencias'!O$5:O$200,A5)) | J5: =IF(A5="","",INDEX('Registro Incidencias'!R$5:R$200,A5)) | K5: =IF(A5="","",INDEX('Registro Incidencias'!AF$5:AF$200,A5)) | L5: =IF(A5="","",INDEX('Registro Incidencias'!AI$5:AI$200,A5)) | M5: =IF(A5="","",INDEX('Registro Incidencias'!AD$5:AD$200,A5)) | N5: =IF(A5="","",INDEX('Registro Incidencias'!AE$5:AE$200,A5)) | O5: =IF(A5="","",INDEX('Registro Incidencias'!AK$5:AK$200,A5)) | P5: =IF(A5="","",INDEX('Registro Incidencias'!AU$5:AU$200,A5)) | Q5: =IF(A5="","",INDEX('Registro Incidencias'!AV$5:AV$200,A5))
A6: =IFERROR(MATCH(1,INDEX(('Registro Incidencias'!AX$5:AX$200="Juan Luis"&TEXT('📅 Semana'!B$7,"YYYYMMDD"))*('Registro Incidencias'!AY$5:AY$200=2),),0),"") | B6: =IF(A6="","",INDEX('Registro Incidencias'!U$5:U$200,A6)) | C6: =IF(A6="","",INDEX('Registro Incidencias'!L$5:L$200,A6)) | D6: =IF(A6="","",INDEX('Registro Incidencias'!A$5:A$200,A6)) | E6: =IF(A6="","",INDEX('Registro Incidencias'!D$5:D$200,A6)) | F6: =IF(A6="","",INDEX('Registro Incidencias'!F$5:F$200,A6)) | G6: =IF(A6="","",INDEX('Registro Incidencias'!G$5:G$200,A6)) | H6: =IF(A6="","",INDEX('Registro Incidencias'!H$5:H$200,A6)) | I6: =IF(A6="","",INDEX('Registro Incidencias'!O$5:O$200,A6)) | J6: =IF(A6="","",INDEX('Registro Incidencias'!R$5:R$200,A6)) | K6: =IF(A6="","",INDEX('Registro Incidencias'!AF$5:AF$200,A6)) | L6: =IF(A6="","",INDEX('Registro Incidencias'!AI$5:AI$200,A6)) | M6: =IF(A6="","",INDEX('Registro Incidencias'!AD$5:AD$200,A6)) | N6: =IF(A6="","",INDEX('Registro Incidencias'!AE$5:AE$200,A6)) | O6: =IF(A6="","",INDEX('Registro Incidencias'!AK$5:AK$200,A6)) | P6: =IF(A6="","",INDEX('Registro Incidencias'!AU$5:AU$200,A6)) | Q6: =IF(A6="","",INDEX('Registro Incidencias'!AV$5:AV$200,A6))
A7: =IFERROR(MATCH(1,INDEX(('Registro Incidencias'!AX$5:AX$200="Juan Luis"&TEXT('📅 Semana'!B$7,"YYYYMMDD"))*('Registro Incidencias'!AY$5:AY$200=3),),0),"") | B7: =IF(A7="","",INDEX('Registro Incidencias'!U$5:U$200,A7)) | C7: =IF(A7="","",INDEX('Registro Incidencias'!L$5:L$200,A7)) | D7: =IF(A7="","",INDEX('Registro Incidencias'!A$5:A$200,A7)) | E7: =IF(A7="","",INDEX('Registro Incidencias'!D$5:D$200,A7)) | F7: =IF(A7="","",INDEX('Registro Incidencias'!F$5:F$200,A7)) | G7: =IF(A7="","",INDEX('Registro Incidencias'!G$5:G$200,A7)) | H7: =IF(A7="","",INDEX('Registro Incidencias'!H$5:H$200,A7)) | I7: =IF(A7="","",INDEX('Registro Incidencias'!O$5:O$200,A7)) | J7: =IF(A7="","",INDEX('Registro Incidencias'!R$5:R$200,A7)) | K7: =IF(A7="","",INDEX('Registro Incidencias'!AF$5:AF$200,A7)) | L7: =IF(A7="","",INDEX('Registro Incidencias'!AI$5:AI$200,A7)) | M7: =IF(A7="","",INDEX('Registro Incidencias'!AD$5:AD$200,A7)) | N7: =IF(A7="","",INDEX('Registro Incidencias'!AE$5:AE$200,A7)) | O7: =IF(A7="","",INDEX('Registro Incidencias'!AK$5:AK$200,A7)) | P7: =IF(A7="","",INDEX('Registro Incidencias'!AU$5:AU$200,A7)) | Q7: =IF(A7="","",INDEX('Registro Incidencias'!AV$5:AV$200,A7))
A8: =IFERROR(MATCH(1,INDEX(('Registro Incidencias'!AX$5:AX$200="Juan Luis"&TEXT('📅 Semana'!B$7,"YYYYMMDD"))*('Registro Incidencias'!AY$5:AY$200=4),),0),"") | B8: =IF(A8="","",INDEX('Registro Incidencias'!U$5:U$200,A8)) | C8: =IF(A8="","",INDEX('Registro Incidencias'!L$5:L$200,A8)) | D8: =IF(A8="","",INDEX('Registro Incidencias'!A$5:A$200,A8)) | E8: =IF(A8="","",INDEX('Registro Incidencias'!D$5:D$200,A8)) | F8: =IF(A8="","",INDEX('Registro Incidencias'!F$5:F$200,A8)) | G8: =IF(A8="","",INDEX('Registro Incidencias'!G$5:G$200,A8)) | H8: =IF(A8="","",INDEX('Registro Incidencias'!H$5:H$200,A8)) | I8: =IF(A8="","",INDEX('Registro Incidencias'!O$5:O$200,A8)) | J8: =IF(A8="","",INDEX('Registro Incidencias'!R$5:R$200,A8)) | K8: =IF(A8="","",INDEX('Registro Incidencias'!AF$5:AF$200,A8)) | L8: =IF(A8="","",INDEX('Registro Incidencias'!AI$5:AI$200,A8)) | M8: =IF(A8="","",INDEX('Registro Incidencias'!AD$5:AD$200,A8)) | N8: =IF(A8="","",INDEX('Registro Incidencias'!AE$5:AE$200,A8)) | O8: =IF(A8="","",INDEX('Registro Incidencias'!AK$5:AK$200,A8)) | P8: =IF(A8="","",INDEX('Registro Incidencias'!AU$5:AU$200,A8)) | Q8: =IF(A8="","",INDEX('Registro Incidencias'!AV$5:AV$200,A8))
A9: =IFERROR(MATCH(1,INDEX(('Registro Incidencias'!AX$5:AX$200="Juan Luis"&TEXT('📅 Semana'!B$7,"YYYYMMDD"))*('Registro Incidencias'!AY$5:AY$200=5),),0),"") | B9: =IF(A9="","",INDEX('Registro Incidencias'!U$5:U$200,A9)) | C9: =IF(A9="","",INDEX('Registro Incidencias'!L$5:L$200,A9)) | D9: =IF(A9="","",INDEX('Registro Incidencias'!A$5:A$200,A9)) | E9: =IF(A9="","",INDEX('Registro Incidencias'!D$5:D$200,A9)) | F9: =IF(A9="","",INDEX('Registro Incidencias'!F$5:F$200,A9)) | G9: =IF(A9="","",INDEX('Registro Incidencias'!G$5:G$200,A9)) | H9: =IF(A9="","",INDEX('Registro Incidencias'!H$5:H$200,A9)) | I9: =IF(A9="","",INDEX('Registro Incidencias'!O$5:O$200,A9)) | J9: =IF(A9="","",INDEX('Registro Incidencias'!R$5:R$200,A9)) | K9: =IF(A9="","",INDEX('Registro Incidencias'!AF$5:AF$200,A9)) | L9: =IF(A9="","",INDEX('Registro Incidencias'!AI$5:AI$200,A9)) | M9: =IF(A9="","",INDEX('Registro Incidencias'!AD$5:AD$200,A9)) | N9: =IF(A9="","",INDEX('Registro Incidencias'!AE$5:AE$200,A9)) | O9: =IF(A9="","",INDEX('Registro Incidencias'!AK$5:AK$200,A9)) | P9: =IF(A9="","",INDEX('Registro Incidencias'!AU$5:AU$200,A9)) | Q9: =IF(A9="","",INDEX('Registro Incidencias'!AV$5:AV$200,A9))
A10: =IFERROR(MATCH(1,INDEX(('Registro Incidencias'!AX$5:AX$200="Juan Luis"&TEXT('📅 Semana'!B$7,"YYYYMMDD"))*('Registro Incidencias'!AY$5:AY$200=6),),0),"") | B10: =IF(A10="","",INDEX('Registro Incidencias'!U$5:U$200,A10)) | C10: =IF(A10="","",INDEX('Registro Incidencias'!L$5:L$200,A10)) | D10: =IF(A10="","",INDEX('Registro Incidencias'!A$5:A$200,A10)) | E10: =IF(A10="","",INDEX('Registro Incidencias'!D$5:D$200,A10)) | F10: =IF(A10="","",INDEX('Registro Incidencias'!F$5:F$200,A10)) | G10: =IF(A10="","",INDEX('Registro Incidencias'!G$5:G$200,A10)) | H10: =IF(A10="","",INDEX('Registro Incidencias'!H$5:H$200,A10)) | I10: =IF(A10="","",INDEX('Registro Incidencias'!O$5:O$200,A10)) | J10: =IF(A10="","",INDEX('Registro Incidencias'!R$5:R$200,A10)) | K10: =IF(A10="","",INDEX('Registro Incidencias'!AF$5:AF$200,A10)) | L10: =IF(A10="","",INDEX('Registro Incidencias'!AI$5:AI$200,A10)) | M10: =IF(A10="","",INDEX('Registro Incidencias'!AD$5:AD$200,A10)) | N10: =IF(A10="","",INDEX('Registro Incidencias'!AE$5:AE$200,A10)) | O10: =IF(A10="","",INDEX('Registro Incidencias'!AK$5:AK$200,A10)) | P10: =IF(A10="","",INDEX('Registro Incidencias'!AU$5:AU$200,A10)) | Q10: =IF(A10="","",INDEX('Registro Incidencias'!AV$5:AV$200,A10))
A11: =COUNTIFS('Registro Incidencias'!S$5:S$200,"Juan Luis",'Registro Incidencias'!T$5:T$200,'📅 Semana'!B$7)&" averías" -> 0 averías | J11: ="Verificadas: "&COUNTIFS(A5:A10,"<>",P5:P10,"<>")&"/"&COUNTIF(A5:A10,"<>") -> Verificadas: 6/6
A13: =TEXT('📅 Semana'!B$8,"DDDD")&" — "&TEXT('📅 Semana'!B$8,"DD/MM/")&"2026" -> martes — 17/02/2026
A14: N.º | B14: HORA | C14: PRIORIDAD | D14: ID INCID. | E14: ABONADO | F14: CLIENTE | G14: DIRECCIÓN | H14: MUNICIPIO | I14: SISTEMA | J14: DESCRIPCIÓN | K14: MATERIAL | L14: PRESUP. | M14: VISITA | N14: MOTIVO REVISITA | O14: ESTADO | P14: 🟢 VERIFICACIÓN NOCTURNA | Q14: 🟢 OPERADOR | R14: 🟢 SISTEMA PENDIENTE | S14: 🟢 INFO EXTRA
A15: =IFERROR(MATCH(1,INDEX(('Registro Incidencias'!AX$5:AX$200="Juan Luis"&TEXT('📅 Semana'!B$8,"YYYYMMDD"))*('Registro Incidencias'!AY$5:AY$200=1),),0),"") | B15: =IF(A15="","",INDEX('Registro Incidencias'!U$5:U$200,A15)) | C15: =IF(A15="","",INDEX('Registro Incidencias'!L$5:L$200,A15)) | D15: =IF(A15="","",INDEX('Registro Incidencias'!A$5:A$200,A15)) | E15: =IF(A15="","",INDEX('Registro Incidencias'!D$5:D$200,A15)) | F15: =IF(A15="","",INDEX('Registro Incidencias'!F$5:F$200,A15)) | G15: =IF(A15="","",INDEX('Registro Incidencias'!G$5:G$200,A15)) | H15: =IF(A15="","",INDEX('Registro Incidencias'!H$5:H$200,A15)) | I15: =IF(A15="","",INDEX('Registro Incidencias'!O$5:O$200,A15)) | J15: =IF(A15="","",INDEX('Registro Incidencias'!R$5:R$200,A15)) | K15: =IF(A15="","",INDEX('Registro Incidencias'!AF$5:AF$200,A15)) | L15: =IF(A15="","",INDEX('Registro Incidencias'!AI$5:AI$200,A15)) | M15: =IF(A15="","",INDEX('Registro Incidencias'!AD$5:AD$200,A15)) | N15: =IF(A15="","",INDEX('Registro Incidencias'!AE$5:AE$200,A15)) | O15: =IF(A15="","",INDEX('Registro Incidencias'!AK$5:AK$200,A15)) | P15: =IF(A15="","",INDEX('Registro Incidencias'!AU$5:AU$200,A15)) | Q15: =IF(A15="","",INDEX('Registro Incidencias'!AV$5:AV$200,A15))
A16: =IFERROR(MATCH(1,INDEX(('Registro Incidencias'!AX$5:AX$200="Juan Luis"&TEXT('📅 Semana'!B$8,"YYYYMMDD"))*('Registro Incidencias'!AY$5:AY$200=2),),0),"") | B16: =IF(A16="","",INDEX('Registro Incidencias'!U$5:U$200,A16)) | C16: =IF(A16="","",INDEX('Registro Incidencias'!L$5:L$200,A16)) | D16: =IF(A16="","",INDEX('Registro Incidencias'!A$5:A$200,A16)) | E16: =IF(A16="","",INDEX('Registro Incidencias'!D$5:D$200,A16)) | F16: =IF(A16="","",INDEX('Registro Incidencias'!F$5:F$200,A16)) | G16: =IF(A16="","",INDEX('Registro Incidencias'!G$5:G$200,A16)) | H16: =IF(A16="","",INDEX('Registro Incidencias'!H$5:H$200,A16)) | I16: =IF(A16="","",INDEX('Registro Incidencias'!O$5:O$200,A16)) | J16: =IF(A16="","",INDEX('Registro Incidencias'!R$5:R$200,A16)) | K16: =IF(A16="","",INDEX('Registro Incidencias'!AF$5:AF$200,A16)) | L16: =IF(A16="","",INDEX('Registro Incidencias'!AI$5:AI$200,A16)) | M16: =IF(A16="","",INDEX('Registro Incidencias'!AD$5:AD$200,A16)) | N16: =IF(A16="","",INDEX('Registro Incidencias'!AE$5:AE$200,A16)) | O16: =IF(A16="","",INDEX('Registro Incidencias'!AK$5:AK$200,A16)) | P16: =IF(A16="","",INDEX('Registro Incidencias'!AU$5:AU$200,A16)) | Q16: =IF(A16="","",INDEX('Registro Incidencias'!AV$5:AV$200,A16))
A17: =IFERROR(MATCH(1,INDEX(('Registro Incidencias'!AX$5:AX$200="Juan Luis"&TEXT('📅 Semana'!B$8,"YYYYMMDD"))*('Registro Incidencias'!AY$5:AY$200=3),),0),"") | B17: =IF(A17="","",INDEX('Registro Incidencias'!U$5:U$200,A17)) | C17: =IF(A17="","",INDEX('Registro Incidencias'!L$5:L$200,A17)) | D17: =IF(A17="","",INDEX('Registro Incidencias'!A$5:A$200,A17)) | E17: =IF(A17="","",INDEX('Registro Incidencias'!D$5:D$200,A17)) | F17: =IF(A17="","",INDEX('Registro Incidencias'!F$5:F$200,A17)) | G17: =IF(A17="","",INDEX('Registro Incidencias'!G$5:G$200,A17)) | H17: =IF(A17="","",INDEX('Registro Incidencias'!H$5:H$200,A17)) | I17: =IF(A17="","",INDEX('Registro Incidencias'!O$5:O$200,A17)) | J17: =IF(A17="","",INDEX('Registro Incidencias'!R$5:R$200,A17)) | K17: =IF(A17="","",INDEX('Registro Incidencias'!AF$5:AF$200,A17)) | L17: =IF(A17="","",INDEX('Registro Incidencias'!AI$5:AI$200,A17)) | M17: =IF(A17="","",INDEX('Registro Incidencias'!AD$5:AD$200,A17)) | N17: =IF(A17="","",INDEX('Registro Incidencias'!AE$5:AE$200,A17)) | O17: =IF(A17="","",INDEX('Registro Incidencias'!AK$5:AK$200,A17)) | P17: =IF(A17="","",INDEX('Registro Incidencias'!AU$5:AU$200,A17)) | Q17: =IF(A17="","",INDEX('Registro Incidencias'!AV$5:AV$200,A17))
A18: =IFERROR(MATCH(1,INDEX(('Registro Incidencias'!AX$5:AX$200="Juan Luis"&TEXT('📅 Semana'!B$8,"YYYYMMDD"))*('Registro Incidencias'!AY$5:AY$200=4),),0),"") | B18: =IF(A18="","",INDEX('Registro Incidencias'!U$5:U$200,A18)) | C18: =IF(A18="","",INDEX('Registro Incidencias'!L$5:L$200,A18)) | D18: =IF(A18="","",INDEX('Registro Incidencias'!A$5:A$200,A18)) | E18: =IF(A18="","",INDEX('Registro Incidencias'!D$5:D$200,A18)) | F18: =IF(A18="","",INDEX('Registro Incidencias'!F$5:F$200,A18)) | G18: =IF(A18="","",INDEX('Registro Incidencias'!G$5:G$200,A18)) | H18: =IF(A18="","",INDEX('Registro Incidencias'!H$5:H$200,A18)) | I18: =IF(A18="","",INDEX('Registro Incidencias'!O$5:O$200,A18)) | J18: =IF(A18="","",INDEX('Registro Incidencias'!R$5:R$200,A18)) | K18: =IF(A18="","",INDEX('Registro Incidencias'!AF$5:AF$200,A18)) | L18: =IF(A18="","",INDEX('Registro Incidencias'!AI$5:AI$200,A18)) | M18: =IF(A18="","",INDEX('Registro Incidencias'!AD$5:AD$200,A18)) | N18: =IF(A18="","",INDEX('Registro Incidencias'!AE$5:AE$200,A18)) | O18: =IF(A18="","",INDEX('Registro Incidencias'!AK$5:AK$200,A18)) | P18: =IF(A18="","",INDEX('Registro Incidencias'!AU$5:AU$200,A18)) | Q18: =IF(A18="","",INDEX('Registro Incidencias'!AV$5:AV$200,A18))
